Workbook

Sheet README
A1: 4ORM FINANCE
A2: Institutional Settlement Layer | 5-Year Financial Escalation Model
A3: KCS Capital | July 2026 | All Figures in Canadian Dollars (CAD)
B5: ABOUT THIS MODEL
B6: This workbook models the 5-year financial trajectory for 4ORM Finance, Canada's institutional settlement layer for tokenized real-world assets.
B7: The platform is being built to serve targeted Alberta and BC financial institutions. Modeled counterparties include ATB Financial, Bow Valley Credit Union, Servus Credit Union, and Vancity Credit Union as illustrative examples of the institution profile 4orm is designed to serve. No partnerships are yet in place; two Memoranda of Understanding are targeted during the Phase 1 pre-seed period.
B8: Revenue model validated against ATB Financial FY2025 Annual Report ($43.3B deposits, $37.2B AUA, $29.1B lending).
B9: Six revenue streams + (Reserved 6th Stream). Modeled ATB revenue in 2028 (post-onboarding) approximately $5.2M (H1 at 50% ramp); approximately $7M at full modeled capacity.
B10: V10 DATA ROOM EDITION: Semi-annual periods (H1/H2). ALL calculations are Excel formulas. SPEER toggle wired at Control Panel B22.
B11: ATB + BVCU modeled to start 2028, Servus + Vancity modeled to start 2029. Change Control Panel inputs to stress test scenarios.
B13: V10 CHANGES FROM V9
B14: SPEER Engineering toggle added (Control Panel B22): when ON, SPEER contracted phases 1-3 are active ($317,304 CAD contract) and internal build lines suppressed to avoid double-counting
B15: SPEER payment schedule updated: deposit shifts to September 1, 2026 (aligning with pre-seed close)
B16: Team rates updated: Chad $8K/mo, Kevin $4K/mo (CMO), CTO $15K/mo (Phase 1 hire), Fractional CFO $6K/mo, Bruce $6K/mo, Dean $5K/mo
B17: Zed Head Architect, Smart Contract Dev, Backend Dev all full-time from H2 2026 (partial-period ramp)
... B93: Date: July 3, 2026

Sheet Control Panel
A1: 4ORM FINANCE - SCENARIO CONTROL PANEL
A2: Set toggles to 1 (ON) or 0 (OFF) - all sheets reference these cells | Yellow cells = editable inputs
A4: Scenario / Vertical | B4: Toggle (1=ON, 0=OFF) | C4: Status | D4: Description
A5: REVENUE STREAMS
A6: Settlement Fees (1.5 bps) | B6: 1 | C6: =IF(B6=1,"ON","OFF") | D6: Deposits x 5x turnover x 1% tokenized x 1.5 bps - 4ORM 30%
A7: Issuance Fees (0.5%) | B7: 1 | C7: =IF(B7=1,"ON","OFF") | D7: Lending x 1.5% tokenized x 0.5% - 4ORM 60%
A8: Trading Fees (5 bps) | B8: 1 | C8: =IF(B8=1,"ON","OFF") | D8: 40% of issuance volume x 5 bps - 4ORM 100%
A9: Custody Fees (30 bps) | B9: 1 | C9: =IF(B9=1,"ON","OFF") | D9: AUA x 1.5% tokenized x 30 bps - 4ORM 40%
A10: SaaS + APIs | B10: 1 | C10: =IF(B10=1,"ON","OFF") | D10: Enterprise clients x $25K/mo - 4ORM 80%
A11: (reserved slot - vertical removed) | B11: 0 | C11: =IF(B11=1,"ON","OFF") | D11: Removed from v10 scope
A13: PARTNER INSTITUTIONS
A14: ATB Financial (Anchor) | B14: 1 | C14: =IF(B14=1,"ON","OFF") | D14: $43.3B deposits - starts 2027 (anchor)
A15: Bow Valley Credit Union | B15: 1 | C15: =IF(B15=1,"ON","OFF") | D15: ~$2B est. - starts 2027
A16: Vancity Credit Union | B16: 1 | C16: =IF(B16=1,"ON","OFF") | D16: $35.5B AUA - starts 2028
A17: Servus Credit Union | B17: 1 | C17: =IF(B17=1,"ON","OFF") | D17: $29.3B assets - starts 2028
A19: BUILD SCENARIOS
A20: platform Build | B20: 1 | C20: =IF(B20=1,"ON","OFF") | D20: MASTER SWITCH: 1 = the platform Build flows to P&L; 0 = Traditional. ~35% headcount savings via developer tooling
A21: Traditional Build | B21: =1-B20 | C21: =IF(B21=1,"ON","OFF") | D21: Full team, no developer tooling - compare side-by-side
A22: SPEER Engineering (External) | B22: 1 | C22: =IF(B22=1,"ON","OFF") | D22: Gates SPEER phases 1-3 + HST on DevEx sheet. Total $317,304 CAD; deposit Sept 1 2026 + 12 monthly installments through Sept 2027
A23: SPEER Fractional CTO | B23: 0 | C23: =IF(B23=1,"ON","OFF") | D23: Gates SPEER Fractional CTO row on DevEx ($18K/half)
A24: SPEER Grants/SR&ED Support | B24: 1 | C24: =IF(B24=1,"ON","OFF") | D24: Gates SR&ED credit line in OpEx (negative expense)
A26: MACRO ASSUMPTIONS
A27: Deposit Tokenization Rate | B27: 0.01 | C27: 1.0% | D27: Percentage of FI deposits tokenized on platform
A28: Issuance/Custody Tokenization Rate | B28: 0.015 | C28: 1.5% | D28: Percentage of lending/AUA tokenized
A29: Deposit Turnover Multiplier | B29: 5 | C29: 5x | D29: Annual turnover on tokenized deposits (settlement volume)
A30: Annual Growth Rate | B30: 0.04 | C30: 4.0% | D30: Conservative YoY growth in volume + adoption
A31: ATB Deposit Base ($B) | B31: 43.3 | C31: $43.3B | D31: Source: ATB Annual Report FY2025
A32: ATB Lending Base ($B) | B32: 29.1 | C32: $29.1B | D32: Source: ATB Annual Report FY2025
A33: ATB AUA ($B) | B33: 37.2 | C33: $37.2B | D33: Source: ATB Annual Report FY2025
A34: Enterprise Clients (ATB) | B34: 20 | C34: 20 | D34: Enterprise SaaS clients at ATB
A35: SaaS Price per Client ($/mo) | B35: 25000 | C35: $25K/mo | D35: Monthly SaaS + API licensing fee
A36: Salary Escalation | B36: 0.03 | C36: 3.0% | D36: Standard Canadian CPI-linked
A37: Infrastructure Escalation | B37: 0.12 | C37: 12.0% | D37: Cloud/blockchain scales with usage
A39: FEE RATES & SPLITS
A40: Stream | B40: Fee Rate | C40: 4ORM Split | D40: Description
A41: Settlement | B41: 0.00015 | C41: 0.3 | D41: 1.5 bps of settlement volume
A42: Issuance | B42: 0.005 | C42: 0.6 | D42: 0.5% of issuance volume
A43: Trading | B43: 0.0005 | C43: 1 | D43: 5 bps of trading volume
A44: Custody | B44: 0.003 | C44: 0.4 | D44: 30 bps of custody AUA
A45: SaaS | B45: =B35*12 | C45: 0.8 | D45: Annual per enterprise client
...

Sheet Summary
A1: 4ORM FINANCE - EXECUTIVE SUMMARY
A2: 5-Year Financial Snapshot | Semi-Annual Periods | the platform Build | 5 Revenue Streams + (reserved) | CAD
A4: KEY METRICS AT A GLANCE | LEAN BUILD vs TRADITIONAL | B4: platform Build | C4: Traditional Build | D4: Efficiency Savings
A5: ATB Year 1 Revenue (4ORM Share) | B5: ='Revenue Model'!D26+'Revenue Model'!E26 | C5: =B5 | D5: N/A - Revenue same | E5: 5 streams: Settlement + Issuance + Trading + Custody + SaaS
A6: 5-Year Total Revenue (4 FIs + (reserved)) | B6: ='5-Year P&L Summary'!M16 | C6: =B6 | D6: N/A - Revenue same | E6: ATB+BVCU (2027) + Servus+Vancity (2028) + (reserved)
A7: 5-Year Total Expenses (platform Build) | B7: ='5-Year P&L Summary'!M24 | C7: =SUM('DevEx - Build Costs'!C36:M37)+SUM('OpEx - Ongoing'!C39:M40) | D7: =C7-B7 | E7: Traditional = +35% DevEx + ~$890K/yr additional comp
A8: 5-Year Net Income | B8: ='5-Year P&L Summary'!M26 | C8: =B6-C7 | D8: =B8-C8 | E8: platform Build generates more profit by reducing expenses
A9: Year 5 Annual Revenue (H2 2031) | B9: ='Revenue Model'!M58 | C9: =B9 | D9: N/A - Revenue same | E9: H2 2031: 4 FIs at full capacity + (reserved)
A10: Blended Gross Margin | B10: =IF('5-Year P&L Summary'!M16=0,0,'5-Year P&L Summary'!M26/'5-Year P&L Summary'!M16) | C10: =IF(B6=0,0,(B6-C7)/B6) | D10: =B10-C10 | E10: platform Build achieves higher margins via lower headcount
A12: 5-YEAR P&L SNAPSHOT (platform BUILD)
B13: H2 2026 | C13: H1 2027 | D13: H2 2027 | E13: H1 2028 | F13: H2 2028 | G13: H1 2029 | H13: H2 2029 | I13: H1 2030 | J13: H2 2030 | K13: H1 2031 | L13: H2 2031 | M13: 5-Year Total
A14: Total Revenue | B14: ='5-Year P&L Summary'!B13 | C14: ='5-Year P&L Summary'!C13 | D14: ='5-Year P&L Summary'!D13 | E14: ='5-Year P&L Summary'!E13 | F14: ='5-Year P&L Summary'!F13 | G14: ='5-Year P&L Summary'!G13 | H14: ='5-Year P&L Summary'!H13 | I14: ='5-Year P&L Summary'!I13 | ... L14: ='5-Year P&L Summary'!L13 | M14: =SUM(B14:L14)
A15: Settlement Fees (1.5 bps) | B15: ='5-Year P&L Summary'!B6 | C15: ='5-Year P&L Summary'!C6 | D15: ='5-Year P&L Summary'!D6 | E15: ='5-Year P&L Summary'!E6 | F15: ='5-Year P&L Summary'!F6 | G15: ='5-Year P&L Summary'!G6 | H15: ='5-Year P&L Summary'!H6 | I15: ='5-Year P&L Summary'!I6 | ... L15: ='5-Year P&L Summary'!L6 | M15: =SUM(B15:L15)
A16: Issuance Fees (0.5%) | B16: ='5-Year P&L Summary'!B7 | C16: ='5-Year P&L Summary'!C7 | D16: ='5-Year P&L Summary'!D7 | E16: ='5-Year P&L Summary'!E7 | F16: ='5-Year P&L Summary'!F7 | G16: ='5-Year P&L Summary'!G7 | H16: ='5-Year P&L Summary'!H7 | I16: ='5-Year P&L Summary'!I7 | ... L16: ='5-Year P&L Summary'!L7 | M16: =SUM(B16:L16)
A17: Trading Fees (5 bps) | B17: ='5-Year P&L Summary'!B8 | C17: ='5-Year P&L Summary'!C8 | D17: ='5-Year P&L Summary'!D8 | E17: ='5-Year P&L Summary'!E8 | F17: ='5-Year P&L Summary'!F8 | G17: ='5-Year P&L Summary'!G8 | H17: ='5-Year P&L Summary'!H8 | I17: ='5-Year P&L Summary'!I8 | ... L17: ='5-Year P&L Summary'!L8 | M17: =SUM(B17:L17)
A18: Custody Fees (30 bps) | B18: ='5-Year P&L Summary'!B9 | C18: ='5-Year P&L Summary'!C9 | D18: ='5-Year P&L Summary'!D9 | E18: ='5-Year P&L Summary'!E9 | F18: ='5-Year P&L Summary'!F9 | G18: ='5-Year P&L Summary'!G9 | H18: ='5-Year P&L Summary'!H9 | I18: ='5-Year P&L Summary'!I9 | ... L18: ='5-Year P&L Summary'!L9 | M18: =SUM(B18:L18)
A19: SaaS + APIs ($25K/mo) | B19: ='5-Year P&L Summary'!B10 | C19: ='5-Year P&L Summary'!C10 | D19: ='5-Year P&L Summary'!D10 | E19: ='5-Year P&L Summary'!E10 | F19: ='5-Year P&L Summary'!F10 | G19: ='5-Year P&L Summary'!G10 | H19: ='5-Year P&L Summary'!H10 | I19: ='5-Year P&L Summary'!I10 | ... L19: ='5-Year P&L Summary'!L10 | M19: =SUM(B19:L19)
A20: (reserved) | B20: ='5-Year P&L Summary'!B11 | C20: ='5-Year P&L Summary'!C11 | D20: ='5-Year P&L Summary'!D11 | E20: ='5-Year P&L Summary'!E11 | F20: ='5-Year P&L Summary'!F11 | G20: ='5-Year P&L Summary'!G11 | H20: ='5-Year P&L Summary'!H11 | I20: ='5-Year P&L Summary'!I11 | ... L20: ='5-Year P&L Summary'!L11 | M20: =SUM(B20:L20)
A21: (Reserved 6th Stream) | B21: ='5-Year P&L Summary'!B12 | C21: ='5-Year P&L Summary'!C12 | D21: ='5-Year P&L Summary'!D12 | E21: ='5-Year P&L Summary'!E12 | F21: ='5-Year P&L Summary'!F12 | G21: ='5-Year P&L Summary'!G12 | H21: ='5-Year P&L Summary'!H12 | I21: ='5-Year P&L Summary'!I12 | ... L21: ='5-Year P&L Summary'!L12 | M21: =SUM(B21:L21)
A22: Total DevEx | B22: ='5-Year P&L Summary'!B19 | C22: ='5-Year P&L Summary'!C19 | D22: ='5-Year P&L Summary'!D19 | E22: ='5-Year P&L Summary'!E19 | F22: ='5-Year P&L Summary'!F19 | G22: ='5-Year P&L Summary'!G19 | H22: ='5-Year P&L Summary'!H19 | I22: ='5-Year P&L Summary'!I19 | ... L22: ='5-Year P&L Summary'!L19 | M22: =SUM(B22:L22)
A23: Total OpEx | B23: ='5-Year P&L Summary'!B22 | C23: ='5-Year P&L Summary'!C22 | D23: ='5-Year P&L Summary'!D22 | E23: ='5-Year P&L Summary'!E22 | F23: ='5-Year P&L Summary'!F22 | G23: ='5-Year P&L Summary'!G22 | H23: ='5-Year P&L Summary'!H22 | I23: ='5-Year P&L Summary'!I22 | ... L23: ='5-Year P&L Summary'!L22 | M23: =SUM(B23:L23)
A24: Total Expenses | B24: ='5-Year P&L Summary'!B24 | C24: ='5-Year P&L Summary'!C24 | D24: ='5-Year P&L Summary'!D24 | E24: ='5-Year P&L Summary'!E24 | F24: ='5-Year P&L Summary'!F24 | G24: ='5-Year P&L Summary'!G24 | H24: ='5-Year P&L Summary'!H24 | I24: ='5-Year P&L Summary'!I24 | ... L24: ='5-Year P&L Summary'!L24 | M24: =SUM(B24:L24)
A25: NET PROFIT (LOSS) | B25: ='5-Year P&L Summary'!B26 | C25: ='5-Year P&L Summary'!C26 | D25: ='5-Year P&L Summary'!D26 | E25: ='5-Year P&L Summary'!E26 | F25: ='5-Year P&L Summary'!F26 | G25: ='5-Year P&L Summary'!G26 | H25: ='5-Year P&L Summary'!H26 | I25: ='5-Year P&L Summary'!I26 | ... L25: ='5-Year P&L Summary'!L26 | M25: =SUM(B25:L25)
A26: Net Margin % | B26: ='5-Year P&L Summary'!B27 | C26: ='5-Year P&L Summary'!C27 | D26: ='5-Year P&L Summary'!D27 | E26: ='5-Year P&L Summary'!E27 | F26: ='5-Year P&L Summary'!F27 | G26: ='5-Year P&L Summary'!G27 | H26: ='5-Year P&L Summary'!H27 | I26: ='5-Year P&L Summary'!I27 | ... L26: ='5-Year P&L Summary'!L27 | M26: =IF(M14=0,0,M25/M14)
A28: LEAN BUILD vs TRADITIONAL BUILD COMPARISON
A29: Metric | B29: H2 2026 | C29: H1 2027 | D29: H2 2027 | E29: H1 2028 | F29: H2 2028 | G29: H1 2029 | H29: H2 2029 | I29: H1 2030 | J29: H2 2030 | K29: H1 2031 | L29: H2 2031 | M29: 5-Year Total
A30: platform Build - Total DevEx | B30: ='DevEx - Build Costs'!C35 | C30: ='DevEx - Build Costs'!D35 | D30: ='DevEx - Build Costs'!E35 | E30: ='DevEx - Build Costs'!F35 | F30: ='DevEx - Build Costs'!G35 | G30: ='DevEx - Build Costs'!H35 | H30: ='DevEx - Build Costs'!I35 | I30: ='DevEx - Build Costs'!J35 | ... L30: ='DevEx - Build Costs'!M35 | M30: =SUM(B30:L30)
A31: platform Build - Total OpEx | B31: ='OpEx - Ongoing'!C38 | C31: ='OpEx - Ongoing'!D38 | D31: ='OpEx - Ongoing'!E38 | E31: ='OpEx - Ongoing'!F38 | F31: ='OpEx - Ongoing'!G38 | G31: ='OpEx - Ongoing'!H38 | H31: ='OpEx - Ongoing'!I38 | I31: ='OpEx - Ongoing'!J38 | ... L31: ='OpEx - Ongoing'!M38 | M31: =SUM(B31:L31)
A32: platform Build - Total Expenses | B32: =B30+B31 | C32: =C30+C31 | D32: =D30+D31 | E32: =E30+E31 | F32: =F30+F31 | G32: =G30+G31 | H32: =H30+H31 | I32: =I30+I31 | ... L32: =L30+L31 | M32: =SUM(B32:L32)
A33: Traditional - Total DevEx (+35%) | B33: ='DevEx - Build Costs'!C36 | C33: ='DevEx - Build Costs'!D36 | D33: ='DevEx - Build Costs'!E36 | E33: ='DevEx - Build Costs'!F36 | F33: ='DevEx - Build Costs'!G36 | G33: ='DevEx - Build Costs'!H36 | H33: ='DevEx - Build Costs'!I36 | I33: ='DevEx - Build Costs'!J36 | ... L33: ='DevEx - Build Costs'!M36 | M33: =SUM(B33:L33)
A34: Traditional - Total OpEx (+~$890K comp) | B34: ='OpEx - Ongoing'!C39 | C34: ='OpEx - Ongoing'!D39 | D34: ='OpEx - Ongoing'!E39 | E34: ='OpEx - Ongoing'!F39 | F34: ='OpEx - Ongoing'!G39 | G34: ='OpEx - Ongoing'!H39 | H34: ='OpEx - Ongoing'!I39 | I34: ='OpEx - Ongoing'!J39 | ... L34: ='OpEx - Ongoing'!M39 | M34: =SUM(B34:L34)
A35: Traditional - Total Expenses | B35: =B33+B34 | C35: =C33+C34 | D35: =D33+D34 | E35: =E33+E34 | F35: =F33+F34 | G35: =G33+G34 | H35: =H33+H34 | I35: =I33+I34 | ... L35: =L33+L34 | M35: =SUM(B35:L35)
A36: EFFICIENCY BUILD SAVINGS | B36: =B35-B32 | C36: =C35-C32 | D36: =D35-D32 | E36: =E35-E32 | F36: =F35-F32 | G36: =G35-G32 | H36: =H35-H32 | I36: =I35-I32 | ... L36: =L35-L32 | M36: =SUM(B36:L36)
A38: REVENUE BY FINANCIAL INSTITUTION
A39: Institution | B39: H2 2026 | C39: H1 2027 | D39: H2 2027 | E39: H1 2028 | F39: H2 2028 | G39: H1 2029 | H39: H2 2029 | I39: H1 2030 | J39: H2 2030 | K39: H1 2031 | L39: H2 2031 | M39: 5-Year Total
A40: ATB Financial | B40: ='Revenue Model'!C26 | C40: ='Revenue Model'!D26 | D40: ='Revenue Model'!E26 | E40: ='Revenue Model'!F26 | F40: ='Revenue Model'!G26 | G40: ='Revenue Model'!H26 | H40: ='Revenue Model'!I26 | I40: ='Revenue Model'!J26 | ... L40: ='Revenue Model'!M26 | M40: =SUM(B40:L40)
A41: Bow Valley CU | B41: ='Revenue Model'!C33 | C41: ='Revenue Model'!D33 | D41: ='Revenue Model'!E33 | E41: ='Revenue Model'!F33 | F41: ='Revenue Model'!G33 | G41: ='Revenue Model'!H33 | H41: ='Revenue Model'!I33 | I41: ='Revenue Model'!J33 | ... L41: ='Revenue Model'!M33 | M41: =SUM(B41:L41)
A42: Vancity Credit Union | B42: ='Revenue Model'!C40 | C42: ='Revenue Model'!D40 | D42: ='Revenue Model'!E40 | E42: ='Revenue Model'!F40 | F42: ='Revenue Model'!G40 | G42: ='Revenue Model'!H40 | H42: ='Revenue Model'!I40 | I42: ='Revenue Model'!J40 | ... L42: ='Revenue Model'!M40 | M42: =SUM(B42:L42)
A43: Servus Credit Union | B43: ='Revenue Model'!C47 | C43: ='Revenue Model'!D47 | D43: ='Revenue Model'!E47 | E43: ='Revenue Model'!F47 | F43: ='Revenue Model'!G47 | G43: ='Revenue Model'!H47 | H43: ='Revenue Model'!I47 | I43: ='Revenue Model'!J47 | ... L43: ='Revenue Model'!M47 | M43: =SUM(B43:L43)
A44: (reserved slot) | B44: ='Revenue Model'!C49 | C44: ='Revenue Model'!D49 | D44: ='Revenue Model'!E49 | E44: ='Revenue Model'!F49 | F44: ='Revenue Model'!G49 | G44: ='Revenue Model'!H49 | H44: ='Revenue Model'!I49 | I44: ='Revenue Model'!J49 | ... L44: ='Revenue Model'!M49 | M44: =SUM(B44:L44)
...

Sheet Team Roadmap
A1: 4ORM FINANCE - 5-YEAR TEAM HIRING ROADMAP | the platform BUILD vs TRADITIONAL BUILD
A2: Phase 1 = Pre-Seed team (Chad, Zed, Kevin, Bruce, Dean, plus CTO + Smart Contract Dev + Backend Dev + DevOps + Exec Asst).
A4: Role | B4: Annual Salary | C4: platform H2 2026 | D4: platform H1 2027 | E4: platform H2 2027 | F4: platform H1 2028 | G4: platform H2 2028 | H4: platform H1 2029 | I4: platform H2 2029 | J4: platform H1 2030 | K4: platform H2 2030 | L4: platform H1 2031 | M4: platform H2 2031 | N4: Trad H2 2026 | O4: Trad H1 2027 | P4: Trad H2 2027 | Q4: Trad H1 2028 | R4: Trad H2 2028 | S4: Trad H1 2029 | T4: Trad H2 2029 | U4: Trad H1 2030 | V4: Trad H2 2030 | W4: Trad H1 2031 | X4: Trad H2 2031 | Y4: platform Build Savings %
A5: EXECUTIVE TEAM
A6: CEO (Chad) | B6: 96000 | C6: 0.5 | D6: 1 | E6: 1 | F6: 1 | G6: 1 | H6: 1 | I6: 1 | J6: 1 | K6: 1 | L6: 1 | M6: 1 | N6: 1 | O6: 1 | P6: 1 | Q6: 1 | R6: 1 | S6: 1 | T6: 1 | U6: 1 | V6: 1 | W6: 1 | X6: 1 | Y6: 0
A7: CTO (Phase 1 hire) | B7: 180000 | C7: 0.5 | D7: 1 | E7: 1 | F7: 1 | G7: 1 | H7: 1 | I7: 1 | J7: 1 | K7: 1 | L7: 1 | M7: 1 | N7: 0 | O7: 0 | P7: 0 | Q7: 1 | R7: 1 | S7: 1 | T7: 1 | U7: 1 | V7: 1 | W7: 1 | X7: 1 | Y7: 0
A8: CCO (Chief Compliance) (Phase 2) | B8: 180000 | C8: 0 | D8: 0 | E8: 0 | F8: 1 | G8: 1 | H8: 1 | I8: 1 | J8: 1 | K8: 1 | L8: 1 | M8: 1 | N8: 0 | O8: 0 | P8: 0 | Q8: 1 | R8: 1 | S8: 1 | T8: 1 | U8: 1 | V8: 1 | W8: 1 | X8: 1 | Y8: 0
A9: CFO (Fractional -> Full-time in Phase 2) | B9: 72000 | C9: 0.15 | D9: 0.3 | E9: 0.3 | F9: 1 | G9: 1 | H9: 1 | I9: 1 | J9: 1 | K9: 1 | L9: 1 | M9: 1 | N9: 1 | O9: 1 | P9: 1 | Q9: 1 | R9: 1 | S9: 1 | T9: 1 | U9: 1 | V9: 1 | W9: 1 | X9: 1 | Y9: 0
A10: General Counsel (Phase 2) | B10: 200000 | C10: 0 | D10: 0 | E10: 0 | F10: 1 | G10: 1 | H10: 1 | I10: 1 | J10: 1 | K10: 1 | L10: 1 | M10: 1 | N10: 0 | O10: 0 | P10: 0 | Q10: 1 | R10: 1 | S10: 1 | T10: 1 | U10: 1 | V10: 1 | W10: 1 | X10: 1 | Y10: 0
A11: ENGINEERING
A12: Head Architect (Zed) | B12: 170000 | C12: 0.5 | D12: 1 | E12: 1 | F12: 1 | G12: 1 | H12: 1 | I12: 1 | J12: 1 | K12: 1 | L12: 1 | M12: 1 | N12: 1 | O12: 1 | P12: 1 | Q12: 1 | R12: 1 | S12: 1 | T12: 1 | U12: 1 | V12: 1 | W12: 1 | X12: 1 | Y12: 0
A13: Backend Developer (starts H2 2026 at 0.5 FTE) | B13: 145000 | C13: 0.5 | D13: 1 | E13: 1 | F13: 1 | G13: 1 | H13: 1 | I13: 1 | J13: 1 | K13: 1 | L13: 1 | M13: 1 | N13: 0 | O13: 1 | P13: 1 | Q13: 2 | R13: 2 | S13: 2 | T13: 2 | U13: 2 | V13: 2 | W13: 2 | X13: 2 | Y13: 0
A14: Backend Developer #2 (Phase 2) | B14: 145000 | C14: 0 | D14: 0 | E14: 0 | F14: 1 | G14: 1 | H14: 1 | I14: 1 | J14: 1 | K14: 1 | L14: 1 | M14: 1 | N14: 1 | O14: 1 | P14: 1 | Q14: 1 | R14: 1 | S14: 1 | T14: 1 | U14: 1 | V14: 1 | W14: 1 | X14: 1 | Y14: 0.27272727
A15: Frontend Developer #1 (Phase 2) | B15: 130000 | C15: 0 | D15: 0 | E15: 0 | F15: 1 | G15: 1 | H15: 1 | I15: 1 | J15: 1 | K15: 1 | L15: 1 | M15: 1 | N15: 0 | O15: 0 | P15: 0 | Q15: 1 | R15: 1 | S15: 1 | T15: 1 | U15: 1 | V15: 1 | W15: 1 | X15: 1 | Y15: 0
A16: Frontend Developer #2 | B16: 130000 | C16: 0 | D16: 0 | E16: 0 | F16: 0 | G16: 0 | H16: 1 | I16: 1 | J16: 1 | K16: 1 | L16: 1 | M16: 1 | N16: 1 | O16: 1 | P16: 1 | Q16: 1 | R16: 1 | S16: 1 | T16: 1 | U16: 1 | V16: 1 | W16: 1 | X16: 1 | Y16: 0.45454545
A17: Smart Contract Developer (starts H2 2026 at 0.5 FTE) | B17: 145000 | C17: 0.5 | D17: 1 | E17: 1 | F17: 1 | G17: 1 | H17: 1 | I17: 1 | J17: 1 | K17: 1 | L17: 1 | M17: 1 | N17: 1 | O17: 1 | P17: 1 | Q17: 1 | R17: 1 | S17: 1 | T17: 1 | U17: 1 | V17: 1 | W17: 1 | X17: 1 | Y17: 0.045454545
A18: DevOps / Infrastructure (0.5 FTE from H1 2027) | B18: 140000 | C18: 0 | D18: 0.5 | E18: 0.5 | F18: 1 | G18: 1 | H18: 1 | I18: 1 | J18: 1 | K18: 1 | L18: 1 | M18: 1 | N18: 0 | O18: 1 | P18: 1 | Q18: 1 | R18: 1 | S18: 1 | T18: 1 | U18: 1 | V18: 1 | W18: 1 | X18: 1 | Y18: 0.13636364
A19: Security Engineer (Phase 2) | B19: 150000 | C19: 0 | D19: 0 | E19: 0 | F19: 1 | G19: 1 | H19: 1 | I19: 1 | J19: 1 | K19: 1 | L19: 1 | M19: 1 | N19: 0 | O19: 0 | P19: 0 | Q19: 1 | R19: 1 | S19: 1 | T19: 1 | U19: 1 | V19: 1 | W19: 1 | X19: 1 | Y19: 0.18181818
A20: QA / Test Engineer | B20: 105000 | C20: 0 | D20: 0 | E20: 0 | F20: 0 | G20: 0 | H20: 1 | I20: 1 | J20: 1 | K20: 1 | L20: 1 | M20: 1 | N20: 1 | O20: 1 | P20: 1 | Q20: 1 | R20: 1 | S20: 1 | T20: 1 | U20: 1 | V20: 1 | W20: 1 | X20: 1 | Y20: 0.45454545
A21: Data Engineer | B21: 130000 | C21: 0 | D21: 0 | E21: 0 | F21: 0 | G21: 0 | H21: 0 | I21: 0 | J21: 1 | K21: 1 | L21: 1 | M21: 1 | N21: 0 | O21: 1 | P21: 1 | Q21: 1 | R21: 1 | S21: 1 | T21: 1 | U21: 1 | V21: 1 | W21: 1 | X21: 1 | Y21: 0.6
A22: UX / UI Designer | B22: 120000 | C22: 0 | D22: 0 | E22: 0 | F22: 0 | G22: 0 | H22: 0 | I22: 0 | J22: 0 | K22: 0 | L22: 0 | M22: 0 | N22: 1 | O22: 1 | P22: 1 | Q22: 1 | R22: 1 | S22: 1 | T22: 1 | U22: 1 | V22: 1 | W22: 1 | X22: 1 | Y22: 1
A23: Data Analyst | B23: 110000 | C23: 0 | D23: 0 | E23: 0 | F23: 0 | G23: 0 | H23: 0 | I23: 0 | J23: 0 | K23: 0 | L23: 0 | M23: 0 | N23: 0 | O23: 0 | P23: 0 | Q23: 1 | R23: 1 | S23: 1 | T23: 1 | U23: 1 | V23: 1 | W23: 1 | X23: 1 | Y23: 1
A24: COMPLIANCE & LEGAL
A25: Compliance Analyst #1 (Phase 2) | B25: 85000 | C25: 0 | D25: 0 | E25: 0 | F25: 1 | G25: 1 | H25: 1 | I25: 1 | J25: 1 | K25: 1 | L25: 1 | M25: 1 | N25: 0 | O25: 0 | P25: 0 | Q25: 1 | R25: 1 | S25: 1 | T25: 1 | U25: 1 | V25: 1 | W25: 1 | X25: 1 | Y25: 0
A26: Compliance Analyst #2 | B26: 85000 | C26: 0 | D26: 0 | E26: 0 | F26: 1 | G26: 1 | H26: 1 | I26: 1 | J26: 1 | K26: 1 | L26: 1 | M26: 1 | N26: 0 | O26: 1 | P26: 1 | Q26: 1 | R26: 1 | S26: 1 | T26: 1 | U26: 1 | V26: 1 | W26: 1 | X26: 1 | Y26: 0.2
A27: AML/KYC Specialist | B27: 95000 | C27: 0 | D27: 0 | E27: 0 | F27: 0 | G27: 0 | H27: 1 | I27: 1 | J27: 1 | K27: 1 | L27: 1 | M27: 1 | N27: 0 | O27: 0 | P27: 0 | Q27: 1 | R27: 1 | S27: 1 | T27: 1 | U27: 1 | V27: 1 | W27: 1 | X27: 1 | Y27: 0.25
A28: Paralegal / Reg Filing | B28: 75000 | C28: 0 | D28: 0 | E28: 0 | F28: 0 | G28: 0 | H28: 1 | I28: 1 | J28: 1 | K28: 1 | L28: 1 | M28: 1 | N28: 0 | O28: 0 | P28: 0 | Q28: 0 | R28: 0 | S28: 1 | T28: 1 | U28: 1 | V28: 1 | W28: 1 | X28: 1 | Y28: 0
A29: OPERATIONS & BUSINESS
A30: Head of Business Dev (Phase 2) | B30: 140000 | C30: 0 | D30: 0 | E30: 0 | F30: 1 | G30: 1 | H30: 1 | I30: 1 | J30: 1 | K30: 1 | L30: 1 | M30: 1 | N30: 0 | O30: 0 | P30: 0 | Q30: 1 | R30: 1 | S30: 1 | T30: 1 | U30: 1 | V30: 1 | W30: 1 | X30: 1 | Y30: 0
A31: Marketing Manager | B31: 110000 | C31: 0 | D31: 0 | E31: 0 | F31: 1 | G31: 1 | H31: 1 | I31: 1 | J31: 1 | K31: 1 | L31: 1 | M31: 1 | N31: 0 | O31: 0 | P31: 0 | Q31: 1 | R31: 1 | S31: 1 | T31: 1 | U31: 1 | V31: 1 | W31: 1 | X31: 1 | Y31: 0
A32: Client Success Manager | B32: 95000 | C32: 0 | D32: 0 | E32: 0 | F32: 0 | G32: 0 | H32: 1 | I32: 1 | J32: 1 | K32: 1 | L32: 1 | M32: 1 | N32: 0 | O32: 0 | P32: 0 | Q32: 0 | R32: 0 | S32: 1 | T32: 1 | U32: 1 | V32: 1 | W32: 1 | X32: 1 | Y32: 0
A33: Operations Manager | B33: 100000 | C33: 0 | D33: 0 | E33: 0 | F33: 0 | G33: 0 | H33: 0 | I33: 0 | J33: 1 | K33: 1 | L33: 1 | M33: 1 | N33: 0 | O33: 0 | P33: 0 | Q33: 0 | R33: 0 | S33: 1 | T33: 1 | U33: 1 | V33: 1 | W33: 1 | X33: 1 | Y33: 0.33333333
A34: Executive Assistant / Ops (0.5 FTE from H1 2027) | B34: 55000 | C34: 0 | D34: 0.545 | E34: 0.545 | F34: 1 | G34: 1 | H34: 1 | I34: 1 | J34: 1 | K34: 1 | L34: 1 | M34: 1 | N34: 0 | O34: 1 | P34: 1 | Q34: 1 | R34: 1 | S34: 1 | T34: 1 | U34: 1 | V34: 1 | W34: 1 | X34: 1 | Y34: 0.27272727
A35: CMO (Kevin) Part-Time | B35: 48000 | C35: 0.5 | D35: 1 | E35: 1 | F35: 1 | G35: 1 | H35: 1 | I35: 1 | J35: 1 | K35: 1 | L35: 1 | M35: 1 | N35: 1 | O35: 1 | P35: 1 | Q35: 1 | R35: 1 | S35: 1 | T35: 1 | U35: 1 | V35: 1 | W35: 1 | X35: 1 | Y35: 0
A36: Founding Capital Markets Advisor (Bruce Fair, via Mench Capital) | B36: 72000 | C36: 0.5 | D36: 1 | E36: 1 | F36: 1 | G36: 1 | H36: 1 | I36: 1 | J36: 1 | K36: 1 | L36: 1 | M36: 1 | N36: 1 | O36: 1 | P36: 1 | Q36: 1 | R36: 1 | S36: 1 | T36: 1 | U36: 1 | V36: 1 | W36: 1 | X36: 1 | Y36: 0
A37: Advisory Council Retainer (Dean McCall) | B37: 60000 | C37: 0.5 | D37: 1 | E37: 1 | F37: 1 | G37: 1 | H37: 1 | I37: 1 | J37: 1 | K37: 1 | L37: 1 | M37: 1 | N37: 1 | O37: 1 | P37: 1 | Q37: 1 | R37: 1 | S37: 1 | T37: 1 | U37: 1 | V37: 1 | W37: 1 | X37: 1 | Y37: 0
A38: TOTAL HEADCOUNT (FTE) | C38: =C6+C7+C8+C9+C10+C12+C13+C14+C15+C16+C17+C18+C19+C20+C21+C22+C23+C25+C26+C27+C28+C30+C31+C32+C33+C34+C35+C36+C37 | D38: =D6+D7+D8+D9+D10+D12+D13+D14+D15+D16+D17+D18+D19+D20+D21+D22+D23+D25+D26+D27+D28+D30+D31+D32+D33+D34+D35+D36+D37 | E38: =E6+E7+E8+E9+E10+E12+E13+E14+E15+E16+E17+E18+E19+E20+E21+E22+E23+E25+E26+E27+E28+E30+E31+E32+E33+E34+E35+E36+E37 | F38: =F6+F7+F8+F9+F10+F12+F13+F14+F15+F16+F17+F18+F19+F20+F21+F22+F23+F25+F26+F27+F28+F30+F31+F32+F33+F34+F35+F36+F37 | G38: =G6+G7+G8+G9+G10+G12+G13+G14+G15+G16+G17+G18+G19+G20+G21+G22+G23+G25+G26+G27+G28+G30+G31+G32+G33+G34+G35+G36+G37 | H38: =H6+H7+H8+H9+H10+H12+H13+H14+H15+H16+H17+H18+H19+H20+H21+H22+H23+H25+H26+H27+H28+H30+H31+H32+H33+H34+H35+H36+H37 | I38: =I6+I7+I8+I9+I10+I12+I13+I14+I15+I16+I17+I18+I19+I20+I21+I22+I23+I25+I26+I27+I28+I30+I31+I32+I33+I34+I35+I36+I37 | J38: =J6+J7+J8+J9+J10+J12+J13+J14+J15+J16+J17+J18+J19+J20+J21+J22+J23+J25+J26+J27+J28+J30+J31+J32+J33+J34+J35+J36+J37 | ... X38: =X6+X7+X8+X9+X10+X12+X13+X14+X15+X16+X17+X18+X19+X20+X21+X22+X23+X25+X26+X27+X28+X30+X31+X32+X33+X34+X35+X36+X37
A39: TOTAL SEMI-ANNUAL COMPENSATION | C39: =($B6*C6/2+$B7*C7/2+$B8*C8/2+$B9*C9/2+$B10*C10/2+$B12*C12/2+$B13*C13/2+$B14*C14/2+$B15*C15/2+$B16*C16/2+$B17*C17/2+$B18*C18/2+$B19*C19/2+$B20*C20/2+$B21*C21/2+$B22*C22/2+$B23*C23/2+$B25*C25/2+$B26*C26/2+$B27*C27/2+$B28*C28/2+$B30*C30/2+$B31*C31/2+$B32*C32/2+$B33*C33/2+$B34*C34/2+$B35*C35/2+$B36*C36/2+$B37*C37/2) | D39: =($B6*D6/2+$B7*D7/2+$B8*D8/2+$B9*D9/2+$B10*D10/2+$B12*D12/2+$B13*D13/2+$B14*D14/2+$B15*D15/2+$B16*D16/2+$B17*D17/2+$B18*D18/2+$B19*D19/2+$B20*D20/2+$B21*D21/2+$B22*D22/2+$B23*D23/2+$B25*D25/2+$B26*D26/2+$B27*D27/2+$B28*D28/2+$B30*D30/2+$B31*D31/2+$B32*D32/2+$B33*D33/2+$B34*D34/2+$B35*D35/2+$B36*D36/2+$B37*D37/2) | E39: =($B6*E6/2+$B7*E7/2+$B8*E8/2+$B9*E9/2+$B10*E10/2+$B12*E12/2+$B13*E13/2+$B14*E14/2+$B15*E15/2+$B16*E16/2+$B17*E17/2+$B18*E18/2+$B19*E19/2+$B20*E20/2+$B21*E21/2+$B22*E22/2+$B23*E23/2+$B25*E25/2+$B26*E26/2+$B27*E27/2+$B28*E28/2+$B30*E30/2+$B31*E31/2+$B32*E32/2+$B33*E33/2+$B34*E34/2+$B35*E35/2+$B36*E36/2+$B37*E37/2) | F39: =($B6*F6/2+$B7*F7/2+$B8*F8/2+$B9*F9/2+$B10*F10/2+$B12*F12/2+$B13*F13/2+$B14*F14/2+$B15*F15/2+$B16*F16/2+$B17*F17/2+$B18*F18/2+$B19*F19/2+$B20*F20/2+$B21*F21/2+$B22*F22/2+$B23*F23/2+$B25*F25/2+$B26*F26/2+$B27*F27/2+$B28*F28/2+$B30*F30/2+$B31*F31/2+$B32*F32/2+$B33*F33/2+$B34*F34/2+$B35*F35/2+$B36*F36/2+$B37*F37/2) | G39: =($B6*G6/2+$B7*G7/2+$B8*G8/2+$B9*G9/2+$B10*G10/2+$B12*G12/2+$B13*G13/2+$B14*G14/2+$B15*G15/2+$B16*G16/2+$B17*G17/2+$B18*G18/2+$B19*G19/2+$B20*G20/2+$B21*G21/2+$B22*G22/2+$B23*G23/2+$B25*G25/2+$B26*G26/2+$B27*G27/2+$B28*G28/2+$B30*G30/2+$B31*G31/2+$B32*G32/2+$B33*G33/2+$B34*G34/2+$B35*G35/2+$B36*G36/2+$B37*G37/2) | H39: =($B6*H6/2+$B7*H7/2+$B8*H8/2+$B9*H9/2+$B10*H10/2+$B12*H12/2+$B13*H13/2+$B14*H14/2+$B15*H15/2+$B16*H16/2+$B17*H17/2+$B18*H18/2+$B19*H19/2+$B20*H20/2+$B21*H21/2+$B22*H22/2+$B23*H23/2+$B25*H25/2+$B26*H26/2+$B27*H27/2+$B28*H28/2+$B30*H30/2+$B31*H31/2+$B32*H32/2+$B33*H33/2+$B34*H34/2+$B35*H35/2+$B36*H36/2+$B37*H37/2) | I39: =($B6*I6/2+$B7*I7/2+$B8*I8/2+$B9*I9/2+$B10*I10/2+$B12*I12/2+$B13*I13/2+$B14*I14/2+$B15*I15/2+$B16*I16/2+$B17*I17/2+$B18*I18/2+$B19*I19/2+$B20*I20/2+$B21*I21/2+$B22*I22/2+$B23*I23/2+$B25*I25/2+$B26*I26/2+$B27*I27/2+$B28*I28/2+$B30*I30/2+$B31*I31/2+$B32*I32/2+$B33*I33/2+$B34*I34/2+$B35*I35/2+$B36*I36/2+$B37*I37/2) | J39: =($B6*J6/2+$B7*J7/2+$B8*J8/2+$B9*J9/2+$B10*J10/2+$B12*J12/2+$B13*J13/2+$B14*J14/2+$B15*J15/2+$B16*J16/2+$B17*J17/2+$B18*J18/2+$B19*J19/2+$B20*J20/2+$B21*J21/2+$B22*J22/2+$B23*J23/2+$B25*J25/2+$B26*J26/2+$B27*J27/2+$B28*J28/2+$B30*J30/2+$B31*J31/2+$B32*J32/2+$B33*J33/2+$B34*J34/2+$B35*J35/2+$B36*J36/2+$B37*J37/2) | ... X39: =($B6*X6/2+$B7*X7/2+$B8*X8/2+$B9*X9/2+$B10*X10/2+$B12*X12/2+$B13*X13/2+$B14*X14/2+$B15*X15/2+$B16*X16/2+$B17*X17/2+$B18*X18/2+$B19*X19/2+$B20*X20/2+$B21*X21/2+$B22*X22/2+$B23*X23/2+$B25*X25/2+$B26*X26/2+$B27*X27/2+$B28*X28/2+$B30*X30/2+$B31*X31/2+$B32*X32/2+$B33*X33/2+$B34*X34/2+$B35*X35/2+$B36*X36/2+$B37*X37/2)
A40: platform SAVINGS (Traditional - the platform Build) | C40: =N39-C39 | D40: =O39-D39 | E40: =P39-E39 | F40: =Q39-F39 | G40: =R39-G39 | H40: =S39-H39 | I40: =T39-I39 | J40: =U39-J39 | ... M40: =X39-M39

Sheet DevEx - Build Costs
A1: 4ORM FINANCE - DEVELOPMENT EXPENSES | SPEER + INTERNAL | EFFICIENT BUILD vs TRADITIONAL
A2: SPEER contracted at $317,304 (3 phases, 13 months). Deposit Sept 1 2026 + 12 monthly installments through Sept 2027. the platform Build reduces internal DevEx via toolchain.
A4: Category / Item | B4: Build Option | C4: H2 2026 | D4: H1 2027 | E4: H2 2027 | F4: H1 2028 | G4: H2 2028 | H4: H1 2029 | I4: H2 2029 | J4: H1 2030 | K4: H2 2030 | L4: H1 2031 | M4: H2 2031 | N4: Total
A5: SPEER ENGINEERING - CONTRACTED BUILD
A6: Phase 1: Discovery & Architecture (1-2 mo) | B6: SPEER | C6: =IF('Control Panel'!$B$22=1,31200,0) | D6: 0 | E6: 0 | F6: 0 | G6: 0 | H6: 0 | I6: 0 | J6: 0 | K6: 0 | L6: 0 | M6: 0 | N6: =SUM(C6:M6)
A7: Phase 2: MVP Design & Dev (3-5 mo) | B7: SPEER | C7: =IF('Control Panel'!$B$22=1,91650,0) | D7: =IF('Control Panel'!$B$22=1,1950,0) | E7: 0 | F7: 0 | G7: 0 | H7: 0 | I7: 0 | J7: 0 | K7: 0 | L7: 0 | M7: 0 | N7: =SUM(C7:M7)
A8: Phase 3: Continued Dev & Integration (3-6 mo) | B8: SPEER | C8: 0 | D8: =IF('Control Panel'!$B$22=1,103350,0) | E8: =IF('Control Panel'!$B$22=1,52650,0) | F8: 0 | G8: 0 | H8: 0 | I8: 0 | J8: 0 | K8: 0 | L8: 0 | M8: 0 | N8: =SUM(C8:M8)
A9: HST 13% on SPEER (auto-calculated) | B9: Tax | C9: =IF('Control Panel'!$B$22=1,(C6+C7+C8)*0.13,0) | D9: =IF('Control Panel'!$B$22=1,(D6+D7+D8)*0.13,0) | E9: =IF('Control Panel'!$B$22=1,(E6+E7+E8)*0.13,0) | F9: =IF('Control Panel'!$B$22=1,(F6+F7+F8)*0.13,0) | G9: =IF('Control Panel'!$B$22=1,(G6+G7+G8)*0.13,0) | H9: =IF('Control Panel'!$B$22=1,(H6+H7+H8)*0.13,0) | I9: =IF('Control Panel'!$B$22=1,(I6+I7+I8)*0.13,0) | J9: =IF('Control Panel'!$B$22=1,(J6+J7+J8)*0.13,0) | ... M9: =IF('Control Panel'!$B$22=1,(M6+M7+M8)*0.13,0) | N9: =SUM(C9:M9)
A10: SPEER Fractional CTO (Option A) | B10: SPEER | C10: 0 | D10: =18000*'Control Panel'!$B$23 | E10: =18000*'Control Panel'!$B$23 | F10: =18000*'Control Panel'!$B$23 | G10: =18000*'Control Panel'!$B$23 | H10: =18000*'Control Panel'!$B$23 | I10: =18000*'Control Panel'!$B$23 | J10: 0 | K10: 0 | L10: 0 | M10: 0 | N10: =SUM(C10:M10)
A11: Chain abstraction layer (internal) | B11: Internal | C11: 40000 | D11: 0 | E11: 0 | F11: 0 | G11: 0 | H11: 0 | I11: 0 | J11: 0 | K11: 0 | L11: 0 | M11: 0 | N11: =SUM(C11:M11)
A12: INTERNAL PLATFORM BUILD (platform Build)
A13: Core exchange engine (matching, order book) | B13: Internal | C13: =IF('Control Panel'!$B$22=1,0,80000) | D13: =IF('Control Panel'!$B$22=1,0,50000) | E13: 0 | F13: 0 | G13: 0 | H13: 0 | I13: 0 | J13: 0 | K13: 0 | L13: 0 | M13: 0 | N13: =SUM(C13:M13)
A14: Smart contract development (patent-differentiated) | B14: Internal | C14: =IF('Control Panel'!$B$22=1,30000,60000) | D14: =IF('Control Panel'!$B$22=1,0,40000) | E14: 0 | F14: 0 | G14: 0 | H14: 0 | I14: 0 | J14: 0 | K14: 0 | L14: 0 | M14: 0 | N14: =SUM(C14:M14)
A15: KYC/AML integration (Deferred - iComply partnership Phase 2) | B15: Vendor+Internal | C15: 0 | D15: 0 | E15: 0 | F15: 30000 | G15: 30000 | H15: 0 | I15: 0 | J15: 0 | K15: 0 | L15: 0 | M15: 0 | N15: =SUM(C15:M15)
A16: Custody integration (Deferred - Phase 2) | B16: Vendor+Internal | C16: 0 | D16: 0 | E16: 0 | F16: 50000 | G16: 30000 | H16: 0 | I16: 0 | J16: 0 | K16: 0 | L16: 0 | M16: 0 | N16: =SUM(C16:M16)
A17: (reserved slot) | C17: 0 | D17: 0 | E17: 0 | F17: 0 | G17: 0 | H17: 0 | I17: 0 | J17: 0 | K17: 0 | L17: 0 | M17: 0 | N17: =SUM(C17:M17)
A18: Secondary market / trading engine | B18: Internal | C18: 0 | D18: =IF('Control Panel'!$B$22=1,0,25000) | E18: =IF('Control Panel'!$B$22=1,0,25000) | F18: =IF('Control Panel'!$B$22=1,0,35000) | G18: =IF('Control Panel'!$B$22=1,0,35000) | H18: 0 | I18: 0 | J18: 0 | K18: 0 | L18: 0 | M18: 0 | N18: =SUM(C18:M18)
A19: Mobile app development | B19: Internal | C19: 0 | D19: 0 | E19: 0 | F19: 37500 | G19: 37500 | H19: 20000 | I19: 20000 | J19: 0 | K19: 0 | L19: 0 | M19: 0 | N19: =SUM(C19:M19)
A20: Multi-chain expansion | B20: Internal | C20: 0 | D20: 0 | E20: 0 | F20: 0 | G20: 0 | H20: 25000 | I20: 25000 | J20: 17500 | K20: 17500 | L20: 0 | M20: 0 | N20: =SUM(C20:M20)
A21: API marketplace for FI integrations | B21: Internal | C21: 0 | D21: 0 | E21: 0 | F21: 0 | G21: 0 | H21: =IF('Control Panel'!$B$22=1,0,20000) | I21: =IF('Control Panel'!$B$22=1,0,20000) | J21: =IF('Control Panel'!$B$22=1,0,12500) | K21: =IF('Control Panel'!$B$22=1,0,12500) | L21: 0 | M21: 0 | N21: =SUM(C21:M21)
A22: Alberta Sandbox admission prep | B22: Internal | C22: 30000 | D22: 20000 | E22: 0 | F22: 0 | G22: 0 | H22: 0 | I22: 0 | J22: 0 | K22: 0 | L22: 0 | M22: 0 | N22: =SUM(C22:M22)
A23: SECURITY & AUDIT
A24: Smart contract audit (initial - Trail of Bits) | B24: External | C24: 0 | D24: 0 | E24: 0 | F24: 80000 | G24: 0 | H24: 0 | I24: 0 | J24: 0 | K24: 0 | L24: 0 | M24: 0 | N24: =SUM(C24:M24)
A25: Smart contract audit (annual re-audit) | B25: External | C25: 0 | D25: 25000 | E25: 25000 | F25: 25000 | G25: 25000 | H25: 25000 | I25: 25000 | J25: 25000 | K25: 25000 | L25: 25000 | M25: 25000 | N25: =SUM(C25:M25)
A26: Penetration testing (initial) | B26: External | C26: 0 | D26: 0 | E26: 0 | F26: 40000 | G26: 0 | H26: 0 | I26: 0 | J26: 0 | K26: 0 | L26: 0 | M26: 0 | N26: =SUM(C26:M26)
A27: Penetration testing (annual) | B27: External | C27: 0 | D27: 12500 | E27: 12500 | F27: 12500 | G27: 12500 | H27: 12500 | I27: 12500 | J27: 12500 | K27: 12500 | L27: 12500 | M27: 12500 | N27: =SUM(C27:M27)
A28: SOC 2 Type II certification | B28: External | C28: 0 | D28: 0 | E28: 0 | F28: 0 | G28: 30000 | H28: 30000 | I28: 0 | J28: 0 | K28: 0 | L28: 0 | M28: 0 | N28: =SUM(C28:M28)
A29: Patent provisional filings | B29: Legal+Filing | C29: 15000 | D29: 0 | E29: 0 | F29: 0 | G29: 0 | H29: 0 | I29: 0 | J29: 0 | K29: 0 | L29: 0 | M29: 0 | N29: =SUM(C29:M29)
A30: REGULATORY & LICENSING (ONE-TIME)
A31: CIRO dealer registration (application) | B31: Legal+Filing | C31: 0 | D31: 0 | E31: 0 | F31: 150000 | G31: 50000 | H31: 50000 | I31: 0 | J31: 0 | K31: 0 | L31: 0 | M31: 0 | N31: =SUM(C31:M31)
A32: CSA prospectus / exemption filing | B32: Legal | C32: 0 | D32: 0 | E32: 0 | F32: 80000 | G32: 20000 | H32: 20000 | I32: 0 | J32: 0 | K32: 0 | L32: 0 | M32: 0 | N32: =SUM(C32:M32)
A33: Legal structuring (token legal opinion) | B33: External | C33: 30000 | D33: 0 | E33: 0 | F33: 30000 | G33: 15000 | H33: 15000 | I33: 0 | J33: 0 | K33: 0 | L33: 0 | M33: 0 | N33: =SUM(C33:M33)
A34: Provincial registrations (AB, BC) | B34: Filing | C34: 10000 | D34: 0 | E34: 0 | F34: 15000 | G34: 0 | H34: 0 | I34: 0 | J34: 0 | K34: 0 | L34: 0 | M34: 0 | N34: =SUM(C34:M34)
A35: TOTAL DevEx (platform Build) | C35: =C6+C7+C8+C9+C10+C11+C13+C14+C15+C16+C17+C18+C19+C20+C21+C22+C24+C25+C26+C27+C28+C29+C31+C32+C33+C34 | D35: =D6+D7+D8+D9+D10+D11+D13+D14+D15+D16+D17+D18+D19+D20+D21+D22+D24+D25+D26+D27+D28+D29+D31+D32+D33+D34 | E35: =E6+E7+E8+E9+E10+E11+E13+E14+E15+E16+E17+E18+E19+E20+E21+E22+E24+E25+E26+E27+E28+E29+E31+E32+E33+E34 | F35: =F6+F7+F8+F9+F10+F11+F13+F14+F15+F16+F17+F18+F19+F20+F21+F22+F24+F25+F26+F27+F28+F29+F31+F32+F33+F34 | G35: =G6+G7+G8+G9+G10+G11+G13+G14+G15+G16+G17+G18+G19+G20+G21+G22+G24+G25+G26+G27+G28+G29+G31+G32+G33+G34 | H35: =H6+H7+H8+H9+H10+H11+H13+H14+H15+H16+H17+H18+H19+H20+H21+H22+H24+H25+H26+H27+H28+H29+H31+H32+H33+H34 | I35: =I6+I7+I8+I9+I10+I11+I13+I14+I15+I16+I17+I18+I19+I20+I21+I22+I24+I25+I26+I27+I28+I29+I31+I32+I33+I34 | J35: =J6+J7+J8+J9+J10+J11+J13+J14+J15+J16+J17+J18+J19+J20+J21+J22+J24+J25+J26+J27+J28+J29+J31+J32+J33+J34 | ... M35: =M6+M7+M8+M9+M10+M11+M13+M14+M15+M16+M17+M18+M19+M20+M21+M22+M24+M25+M26+M27+M28+M29+M31+M32+M33+M34 | N35: =SUM(C35:M35)
A36: TOTAL DevEx (Traditional Build - +35% internal) | C36: =C35*1.35 | D36: =D35*1.35 | E36: =E35*1.35 | F36: =F35*1.35 | G36: =G35*1.35 | H36: =H35*1.35 | I36: =I35*1.35 | J36: =J35*1.35 | ... M36: =M35*1.35 | N36: =SUM(C36:M36)
A37: EFFICIENT BUILD SAVINGS | C37: =C36-C35 | D37: =D36-D35 | E37: =E36-E35 | F37: =F36-F35 | G37: =G36-G35 | H37: =H36-H35 | I37: =I36-I35 | J37: =J36-J35 | ... M37: =M36-M35

Sheet OpEx - Ongoing
A1: 4ORM FINANCE - OPERATING EXPENSES | the platform BUILD vs TRADITIONAL COMPARE
A2: platform Build = lower team cost, higher tooling | Traditional = full team, no tooling
A4: Category / Item | B4: Escalation | C4: platform H2 2026 | D4: platform H1 2027 | E4: platform H2 2027 | F4: platform H1 2028 | G4: platform H2 2028 | H4: platform H1 2029 | I4: platform H2 2029 | J4: platform H1 2030 | K4: platform H2 2030 | L4: platform H1 2031 | M4: platform H2 2031 | N4: Trad Delta | O4: Notes
A5: TEAM COMPENSATION (platform Build)
A6: Team Comp (linked to Team Roadmap row 39 - the platform Build) | B6: 3% raises/yr | C6: ='Team Roadmap'!C39 | D6: ='Team Roadmap'!D39 | E6: ='Team Roadmap'!E39 | F6: ='Team Roadmap'!F39 | G6: ='Team Roadmap'!G39 | H6: ='Team Roadmap'!H39 | I6: ='Team Roadmap'!I39 | J6: ='Team Roadmap'!J39 | ... M6: ='Team Roadmap'!M39 | O6: efficiency-augmented team
A7: Benefits & Payroll Tax (rate in B7) | B7: 0.18 | C7: =C6*$B$7 | D7: =D6*$B$7 | E7: =E6*$B$7 | F7: =F6*$B$7 | G7: =G6*$B$7 | H7: =H6*$B$7 | I7: =I6*$B$7 | J7: =J6*$B$7 | ... M7: =M6*$B$7 | O7: CPP, EI, health, RRSP
A8: Advisor cash retainers (memo - included in Team Comp above) | B8: 3% raises/yr | C8: 0 | D8: 0 | E8: 0 | F8: 0 | G8: 0 | H8: 0 | I8: 0 | J8: 0 | K8: 0 | L8: 0 | M8: 0 | O8: Bruce+Dean+CFO+Kevin PT (already in Team Roadmap)
A9: DEVELOPER TOOLING & PLATFORMS
A10: GitHub Copilot Business (5-8 seats) | B10: 5%/yr | C10: 2850 | D10: 2850 | E10: 2850 | F10: 2992 | G10: 2992 | H10: 3142 | I10: 3142 | J10: 3300 | K10: 3300 | L10: 3464 | M10: 3464 | N10: -$6.9K
A11: Cursor Pro (5-8 seats) | B11: 5%/yr | C11: 600 | D11: 600 | E11: 600 | F11: 630 | G11: 630 | H11: 662 | I11: 662 | J11: 694 | K11: 694 | L11: 730 | M11: 730 | N11: -$1.5K
A12: Snyk (Team) | B12: 5%/yr | C12: 3000 | D12: 3000 | E12: 3000 | F12: 3150 | G12: 3150 | H12: 3308 | I12: 3308 | J12: 3473 | K12: 3473 | L12: 3646 | M12: 3646 | N12: -$7.3K
A13: Codiumplatform + CodeRabbit | B13: 5%/yr | C13: 2100 | D13: 2100 | E13: 2100 | F13: 2205 | G13: 2205 | H13: 2316 | I13: 2316 | J13: 2431 | K13: 2431 | L13: 2552 | M13: 2552 | N13: -$5.1K
A14: Datadog (Pro) | B14: 10%/yr | C14: 9000 | D14: 9000 | E14: 9000 | F14: 9900 | G14: 9900 | H14: 10890 | I14: 10890 | J14: 11979 | K14: 11979 | L14: 13177 | M14: 13177 | N14: $0 | O14: Needed either way
A15: Claude API + Openplatform API | B15: 12%/yr | C15: 4800 | D15: 4800 | E15: 4800 | F15: 5376 | G15: 5376 | H15: 6021 | I15: 6021 | J15: 6744 | K15: 6744 | L15: 7553 | M15: 7553 | N15: -$15.1K
A16: Mintlify + v0 Vercel | B16: 5%/yr | C16: 1020 | D16: 1020 | E16: 1020 | F16: 1071 | G16: 1071 | H16: 1124 | I16: 1124 | J16: 1181 | K16: 1181 | L16: 1240 | M16: 1240 | N16: -$2.5K
A17: REGULATORY & COMPLIANCE
A18: CIRO/CSA annual fees | B18: 3%/yr | C18: 0 | D18: 0 | E18: 0 | F18: 0 | G18: 30900 | H18: 31827 | I18: 31827 | J18: 32782 | K18: 32782 | L18: 33766 | M18: 33766 | N18: $0
A19: External legal counsel | B19: 5%/yr | C19: 50000 | D19: 50000 | E19: 50000 | F19: 52500 | G19: 52500 | H19: 55125 | I19: 55125 | J19: 57882 | K19: 57882 | L19: 60776 | M19: 60776 | N19: $0
A20: Audit & accounting | B20: 5%/yr | C20: 30000 | D20: 30000 | E20: 37500 | F20: 39375 | G20: 39375 | H20: 41344 | I20: 41344 | J20: 43411 | K20: 43411 | L20: 45582 | M20: 45582 | N20: $0
A21: Compliance software (Chainalysis) | B21: 8%/yr | C21: 0 | D21: 0 | E21: 0 | F21: 0 | G21: 27000 | H21: 29160 | I21: 29160 | J21: 31493 | K21: 31493 | L21: 34012 | M21: 34012 | N21: $0
A22: Insurance (D&O, E&O, Cyber) | B22: 10%/yr | C22: 30000 | D22: 30000 | E22: 50000 | F22: 55000 | G22: 55000 | H22: 60500 | I22: 60500 | J22: 66550 | K22: 66550 | L22: 73205 | M22: 73205 | N22: $0
A23: Licensing & reg filings | B23: 3%/yr | C23: 5000 | D23: 5000 | E23: 7500 | F23: 7725 | G23: 7725 | H23: 7957 | I23: 7957 | J23: 8196 | K23: 8196 | L23: 8441 | M23: 8441 | N23: $0
A24: TECHNOLOGY & INFRASTRUCTURE
A25: Cloud hosting (AWS/Azure) | B25: 15%/yr | C25: 18000 | D25: 18000 | E25: 18000 | F25: 20700 | G25: 20700 | H25: 23805 | I25: 23805 | J25: 27376 | K25: 27376 | L25: 31482 | M25: 31482 | N25: $0
A26: Blockchain infra (nodes/RPC) | B26: 10%/yr | C26: 12000 | D26: 12000 | E26: 12000 | F26: 13200 | G26: 13200 | H26: 14520 | I26: 14520 | J26: 15972 | K26: 15972 | L26: 17569 | M26: 17569 | N26: $0
A27: API & data services | B27: 5%/yr | C27: 6000 | D27: 6000 | E27: 6000 | F27: 6300 | G27: 6300 | H27: 6615 | I27: 6615 | J27: 6946 | K27: 6946 | L27: 7293 | M27: 7293 | N27: $0
A28: Cybersecurity & monitoring | B28: 8%/yr | C28: 9000 | D28: 9000 | E28: 9000 | F28: 9720 | G28: 9720 | H28: 10498 | I28: 10498 | J28: 11338 | K28: 11338 | L28: 12244 | M28: 12244 | N28: $0
A29: DR, backups, CDN, SSL | B29: 4%/yr | C29: 6000 | D29: 6000 | E29: 6000 | F29: 6240 | G29: 6240 | H29: 6490 | I29: 6490 | J29: 6749 | K29: 6749 | L29: 7019 | M29: 7019 | N29: $0
A30: OPERATIONS & OVERHEAD
A31: Office rent & utilities | B31: 5%/yr | C31: 12000 | D31: 12000 | E31: 18000 | F31: 24000 | G31: 24000 | H31: 30000 | I31: 30000 | J31: 36000 | K31: 36000 | L31: 42000 | M31: 42000 | N31: +$12K/yr
A32: Travel & conferences | B32: 10%/yr | C32: 10000 | D32: 10000 | E32: 7500 | F32: 10000 | G32: 10000 | H32: 12500 | I32: 12500 | J32: 15000 | K32: 15000 | L32: 17500 | M32: 17500 | N32: $0
A33: Marketing & BD | B33: 25%/yr | C33: 10000 | D33: 10000 | E33: 7500 | F33: 12500 | G33: 12500 | H33: 20000 | I33: 20000 | J33: 30000 | K33: 30000 | L33: 40000 | M33: 40000 | N33: $0
A34: HR & recruitment | B34: 20%/yr | C34: 2000 | D34: 2000 | E34: 5000 | F34: 7500 | G34: 7500 | H34: 10000 | I34: 10000 | J34: 15000 | K34: 15000 | L34: 20000 | M34: 20000 | N34: +$15K/yr
A35: Office supplies & misc. | B35: 5%/yr | C35: 2000 | D35: 2000 | E35: 2500 | F35: 3000 | G35: 3000 | H35: 3750 | I35: 3750 | J35: 4500 | K35: 4500 | L35: 5000 | M35: 5000 | N35: $0
A36: Software subs (general) | B36: 5%/yr | C36: 5000 | D36: 5000 | E36: 7760 | F36: 8148 | G36: 8148 | H36: 8556 | I36: 8556 | J36: 8983 | K36: 8983 | L36: 9432 | M36: 9432 | N36: $0
A37: SR&ED Tax Credit (gated by CP toggle B24) | B37: - | C37: =-10000*'Control Panel'!$B$24 | D37: =-10000*'Control Panel'!$B$24 | E37: =-15000*'Control Panel'!$B$24 | F37: =-15000*'Control Panel'!$B$24 | G37: =-15000*'Control Panel'!$B$24 | H37: =-12500*'Control Panel'!$B$24 | I37: =-12500*'Control Panel'!$B$24 | J37: =-10000*'Control Panel'!$B$24 | K37: =-10000*'Control Panel'!$B$24 | L37: =-7500*'Control Panel'!$B$24 | M37: =-7500*'Control Panel'!$B$24 | N37: $0 | O37: Est. 15-20% of eligible R&D
A38: TOTAL OpEx (platform Build) | C38: =C6+C7+C8+C10+C11+C12+C13+C14+C15+C16+C18+C19+C20+C21+C22+C23+C25+C26+C27+C28+C29+C31+C32+C33+C34+C35+C36+C37 | D38: =D6+D7+D8+D10+D11+D12+D13+D14+D15+D16+D18+D19+D20+D21+D22+D23+D25+D26+D27+D28+D29+D31+D32+D33+D34+D35+D36+D37 | E38: =E6+E7+E8+E10+E11+E12+E13+E14+E15+E16+E18+E19+E20+E21+E22+E23+E25+E26+E27+E28+E29+E31+E32+E33+E34+E35+E36+E37 | F38: =F6+F7+F8+F10+F11+F12+F13+F14+F15+F16+F18+F19+F20+F21+F22+F23+F25+F26+F27+F28+F29+F31+F32+F33+F34+F35+F36+F37 | G38: =G6+G7+G8+G10+G11+G12+G13+G14+G15+G16+G18+G19+G20+G21+G22+G23+G25+G26+G27+G28+G29+G31+G32+G33+G34+G35+G36+G37 | H38: =H6+H7+H8+H10+H11+H12+H13+H14+H15+H16+H18+H19+H20+H21+H22+H23+H25+H26+H27+H28+H29+H31+H32+H33+H34+H35+H36+H37 | I38: =I6+I7+I8+I10+I11+I12+I13+I14+I15+I16+I18+I19+I20+I21+I22+I23+I25+I26+I27+I28+I29+I31+I32+I33+I34+I35+I36+I37 | J38: =J6+J7+J8+J10+J11+J12+J13+J14+J15+J16+J18+J19+J20+J21+J22+J23+J25+J26+J27+J28+J29+J31+J32+J33+J34+J35+J36+J37 | ... M38: =M6+M7+M8+M10+M11+M12+M13+M14+M15+M16+M18+M19+M20+M21+M22+M23+M25+M26+M27+M28+M29+M31+M32+M33+M34+M35+M36+M37
A39: TOTAL OpEx (Traditional - Trad comp from Roadmap, developer tooling zero) | C39: =C38-('Team Roadmap'!C39*(1+$B$7))+('Team Roadmap'!N39*(1+$B$7))-(C10+C11+C12+C13+C15+C16) | D39: =D38-('Team Roadmap'!D39*(1+$B$7))+('Team Roadmap'!O39*(1+$B$7))-(D10+D11+D12+D13+D15+D16) | E39: =E38-('Team Roadmap'!E39*(1+$B$7))+('Team Roadmap'!P39*(1+$B$7))-(E10+E11+E12+E13+E15+E16) | F39: =F38-('Team Roadmap'!F39*(1+$B$7))+('Team Roadmap'!Q39*(1+$B$7))-(F10+F11+F12+F13+F15+F16) | G39: =G38-('Team Roadmap'!G39*(1+$B$7))+('Team Roadmap'!R39*(1+$B$7))-(G10+G11+G12+G13+G15+G16) | H39: =H38-('Team Roadmap'!H39*(1+$B$7))+('Team Roadmap'!S39*(1+$B$7))-(H10+H11+H12+H13+H15+H16) | I39: =I38-('Team Roadmap'!I39*(1+$B$7))+('Team Roadmap'!T39*(1+$B$7))-(I10+I11+I12+I13+I15+I16) | J39: =J38-('Team Roadmap'!J39*(1+$B$7))+('Team Roadmap'!U39*(1+$B$7))-(J10+J11+J12+J13+J15+J16) | ... M39: =M38-('Team Roadmap'!M39*(1+$B$7))+('Team Roadmap'!X39*(1+$B$7))-(M10+M11+M12+M13+M15+M16)
A40: platform BUILD SEMI-ANNUAL SAVINGS | C40: =C39-C38 | D40: =D39-D38 | E40: =E39-E38 | F40: =F39-F38 | G40: =G39-G38 | H40: =H39-H38 | I40: =I39-I38 | J40: =J39-J38 | ... M40: =M39-M38
A42: CORPORATE STRUCTURE NOTE
...

Sheet Revenue Model
A1: 4ORM FINANCE - 5-YEAR REVENUE MODEL | 5 STREAMS + RESERVED 6TH STREAM (placeholder)
A2: Fee pool split model per Master Pro Forma | ALL CALCULATIONS DRIVEN BY CONTROL PANEL
A4: CONTROL PANEL REFERENCES (for transparency)
A5: ATB Financial - Base Data | B5: ='Control Panel'!B49 | C5: ='Control Panel'!C49 | D5: ='Control Panel'!D49 | E5: ='Control Panel'!E49
A6: Tokenization Rates | B6: ='Control Panel'!B27 | C6: ='Control Panel'!B28
A7: Deposit Turnover | B7: ='Control Panel'!B29
A8: Annual Growth | B8: ='Control Panel'!B30
A10: TOKENIZATION PARAMETERS & FEE STRUCTURE
A11: Stream | B11: Fee Rate (CP) | C11: 4ORM Split (CP) | D11: Description
A12: Settlement | B12: ='Control Panel'!B41 | C12: ='Control Panel'!C41 | D12: 1.5 bps of settlement volume
A13: Issuance | B13: ='Control Panel'!B42 | C13: ='Control Panel'!C42 | D13: 0.5% of issuance volume
A14: Trading | B14: ='Control Panel'!B43 | C14: ='Control Panel'!C43 | D14: 5 bps of trading volume
A15: Custody | B15: ='Control Panel'!B44 | C15: ='Control Panel'!C44 | D15: 30 bps of custody AUA
A16: SaaS + APIs | B16: ='Control Panel'!B45 | C16: ='Control Panel'!C45 | D16: Annual per enterprise client
A18: 5-YEAR REVENUE BY FINANCIAL INSTITUTION (SEMI-ANNUAL)
A19: Revenue Source | B19: Onboard | C19: H2 2026 | D19: H1 2027 | E19: H2 2027 | F19: H1 2028 | G19: H2 2028 | H19: H1 2029 | I19: H2 2029 | J19: H1 2030 | K19: H2 2030 | L19: H1 2031 | M19: H2 2031 | N19: 5-Year Total
A20: ATB FINANCIAL ($43.3B deposits)
A21: Settlement (1.5 bps, 30%) | B21: H1 2028 | C21: ='Control Panel'!$B$14*'Control Panel'!$B$6*'Control Panel'!B49*1000000*'Control Panel'!$B$29*IF('Control Panel'!$B$100=1,'Control Panel'!B$98,'Control Panel'!$B$27)*'Control Panel'!$B$41*'Control Panel'!$C$41*'Control Panel'!B$56*(1+IF('Control Panel'!$D$90=1,'Control Panel'!$C$90,'Control Panel'!$B$30))^MAX(0,(0-'Control Panel'!$F$49)/2)*0.5 | D21: ='Control Panel'!$B$14*'Control Panel'!$B$6*'Control Panel'!B49*1000000*'Control Panel'!$B$29*IF('Control Panel'!$B$100=1,'Control Panel'!C$98,'Control Panel'!$B$27)*'Control Panel'!$B$41*'Control Panel'!$C$41*'Control Panel'!C$56*(1+IF('Control Panel'!$D$90=1,'Control Panel'!$C$90,'Control Panel'!$B$30))^MAX(0,(1-'Control Panel'!$F$49)/2)*0.5 | E21: ='Control Panel'!$B$14*'Control Panel'!$B$6*'Control Panel'!B49*1000000*'Control Panel'!$B$29*IF('Control Panel'!$B$100=1,'Control Panel'!D$98,'Control Panel'!$B$27)*'Control Panel'!$B$41*'Control Panel'!$C$41*'Control Panel'!D$56*(1+IF('Control Panel'!$D$90=1,'Control Panel'!$C$90,'Control Panel'!$B$30))^MAX(0,(2-'Control Panel'!$F$49)/2)*0.5 | F21: ='Control Panel'!$B$14*'Control Panel'!$B$6*'Control Panel'!B49*1000000*'Control Panel'!$B$29*IF('Control Panel'!$B$100=1,'Control Panel'!E$98,'Control Panel'!$B$27)*'Control Panel'!$B$41*'Control Panel'!$C$41*'Control Panel'!E$56*(1+IF('Control Panel'!$D$90=1,'Control Panel'!$C$90,'Control Panel'!$B$30))^MAX(0,(3-'Control Panel'!$F$49)/2)*0.5 | G21: ='Control Panel'!$B$14*'Control Panel'!$B$6*'Control Panel'!B49*1000000*'Control Panel'!$B$29*IF('Control Panel'!$B$100=1,'Control Panel'!F$98,'Control Panel'!$B$27)*'Control Panel'!$B$41*'Control Panel'!$C$41*'Control Panel'!F$56*(1+IF('Control Panel'!$D$90=1,'Control Panel'!$C$90,'Control Panel'!$B$30))^MAX(0,(4-'Control Panel'!$F$49)/2)*0.5 | H21: ='Control Panel'!$B$14*'Control Panel'!$B$6*'Control Panel'!B49*1000000*'Control Panel'!$B$29*IF('Control Panel'!$B$100=1,'Control Panel'!G$98,'Control Panel'!$B$27)*'Control Panel'!$B$41*'Control Panel'!$C$41*'Control Panel'!G$56*(1+IF('Control Panel'!$D$90=1,'Control Panel'!$C$90,'Control Panel'!$B$30))^MAX(0,(5-'Control Panel'!$F$49)/2)*0.5 | I21: ='Control Panel'!$B$14*'Control Panel'!$B$6*'Control Panel'!B49*1000000*'Control Panel'!$B$29*IF('Control Panel'!$B$100=1,'Control Panel'!H$98,'Control Panel'!$B$27)*'Control Panel'!$B$41*'Control Panel'!$C$41*'Control Panel'!H$56*(1+IF('Control Panel'!$D$90=1,'Control Panel'!$C$90,'Control Panel'!$B$30))^MAX(0,(6-'Control Panel'!$F$49)/2)*0.5 | J21: ='Control Panel'!$B$14*'Control Panel'!$B$6*'Control Panel'!B49*1000000*'Control Panel'!$B$29*IF('Control Panel'!$B$100=1,'Control Panel'!I$98,'Control Panel'!$B$27)*'Control Panel'!$B$41*'Control Panel'!$C$41*'Control Panel'!I$56*(1+IF('Control Panel'!$D$90=1,'Control Panel'!$C$90,'Control Panel'!$B$30))^MAX(0,(7-'Control Panel'!$F$49)/2)*0.5 | K21: ='Control Panel'!$B$14*'Control Panel'!$B$6*'Control Panel'!B49*1000000*'Control Panel'!$B$29*IF('Control Panel'!$B$100=1,'Control Panel'!J$98,'Control Panel'!$B$27)*'Control Panel'!$B$41*'Control Panel'!$C$41*'Control Panel'!J$56*(1+IF('Control Panel'!$D$90=1,'Control Panel'!$C$90,'Control Panel'!$B$30))^MAX(0,(8-'Control Panel'!$F$49)/2)*0.5 | L21: ='Control Panel'!$B$14*'Control Panel'!$B$6*'Control Panel'!B49*1000000*'Control Panel'!$B$29*IF('Control Panel'!$B$100=1,'Control Panel'!K$98,'Control Panel'!$B$27)*'Control Panel'!$B$41*'Control Panel'!$C$41*'Control Panel'!K$56*(1+IF('Control Panel'!$D$90=1,'Control Panel'!$C$90,'Control Panel'!$B$30))^MAX(0,(9-'Control Panel'!$F$49)/2)*0.5 | M21: ='Control Panel'!$B$14*'Control Panel'!$B$6*'Control Panel'!B49*1000000*'Control Panel'!$B$29*IF('Control Panel'!$B$100=1,'Control Panel'!L$98,'Control Panel'!$B$27)*'Control Panel'!$B$41*'Control Panel'!$C$41*'Control Panel'!L$56*(1+IF('Control Panel'!$D$90=1,'Control Panel'!$C$90,'Control Panel'!$B$30))^MAX(0,(10-'Control Panel'!$F$49)/2)*0.5 | N21: =SUM(C21:M21)
A22: Issuance (0.5%, 60%) | B22: H1 2028 | C22: ='Control Panel'!$B$14*'Control Panel'!$B$7*'Control Panel'!C49*1000000*IF('Control Panel'!$B$100=1,'Control Panel'!B$99,'Control Panel'!$B$28)*'Control Panel'!$B$42*'Control Panel'!$C$42*'Control Panel'!B$56*(1+IF('Control Panel'!$D$90=1,'Control Panel'!$C$90,'Control Panel'!$B$30))^MAX(0,(0-'Control Panel'!$F$49)/2)*0.5 | D22: ='Control Panel'!$B$14*'Control Panel'!$B$7*'Control Panel'!C49*1000000*IF('Control Panel'!$B$100=1,'Control Panel'!C$99,'Control Panel'!$B$28)*'Control Panel'!$B$42*'Control Panel'!$C$42*'Control Panel'!C$56*(1+IF('Control Panel'!$D$90=1,'Control Panel'!$C$90,'Control Panel'!$B$30))^MAX(0,(1-'Control Panel'!$F$49)/2)*0.5 | E22: ='Control Panel'!$B$14*'Control Panel'!$B$7*'Control Panel'!C49*1000000*IF('Control Panel'!$B$100=1,'Control Panel'!D$99,'Control Panel'!$B$28)*'Control Panel'!$B$42*'Control Panel'!$C$42*'Control Panel'!D$56*(1+IF('Control Panel'!$D$90=1,'Control Panel'!$C$90,'Control Panel'!$B$30))^MAX(0,(2-'Control Panel'!$F$49)/2)*0.5 | F22: ='Control Panel'!$B$14*'Control Panel'!$B$7*'Control Panel'!C49*1000000*IF('Control Panel'!$B$100=1,'Control Panel'!E$99,'Control Panel'!$B$28)*'Control Panel'!$B$42*'Control Panel'!$C$42*'Control Panel'!E$56*(1+IF('Control Panel'!$D$90=1,'Control Panel'!$C$90,'Control Panel'!$B$30))^MAX(0,(3-'Control Panel'!$F$49)/2)*0.5 | G22: ='Control Panel'!$B$14*'Control Panel'!$B$7*'Control Panel'!C49*1000000*IF('Control Panel'!$B$100=1,'Control Panel'!F$99,'Control Panel'!$B$28)*'Control Panel'!$B$42*'Control Panel'!$C$42*'Control Panel'!F$56*(1+IF('Control Panel'!$D$90=1,'Control Panel'!$C$90,'Control Panel'!$B$30))^MAX(0,(4-'Control Panel'!$F$49)/2)*0.5 | H22: ='Control Panel'!$B$14*'Control Panel'!$B$7*'Control Panel'!C49*1000000*IF('Control Panel'!$B$100=1,'Control Panel'!G$99,'Control Panel'!$B$28)*'Control Panel'!$B$42*'Control Panel'!$C$42*'Control Panel'!G$56*(1+IF('Control Panel'!$D$90=1,'Control Panel'!$C$90,'Control Panel'!$B$30))^MAX(0,(5-'Control Panel'!$F$49)/2)*0.5 | I22: ='Control Panel'!$B$14*'Control Panel'!$B$7*'Control Panel'!C49*1000000*IF('Control Panel'!$B$100=1,'Control Panel'!H$99,'Control Panel'!$B$28)*'Control Panel'!$B$42*'Control Panel'!$C$42*'Control Panel'!H$56*(1+IF('Control Panel'!$D$90=1,'Control Panel'!$C$90,'Control Panel'!$B$30))^MAX(0,(6-'Control Panel'!$F$49)/2)*0.5 | J22: ='Control Panel'!$B$14*'Control Panel'!$B$7*'Control Panel'!C49*1000000*IF('Control Panel'!$B$100=1,'Control Panel'!I$99,'Control Panel'!$B$28)*'Control Panel'!$B$42*'Control Panel'!$C$42*'Control Panel'!I$56*(1+IF('Control Panel'!$D$90=1,'Control Panel'!$C$90,'Control Panel'!$B$30))^MAX(0,(7-'Control Panel'!$F$49)/2)*0.5 | K22: ='Control Panel'!$B$14*'Control Panel'!$B$7*'Control Panel'!C49*1000000*IF('Control Panel'!$B$100=1,'Control Panel'!J$99,'Control Panel'!$B$28)*'Control Panel'!$B$42*'Control Panel'!$C$42*'Control Panel'!J$56*(1+IF('Control Panel'!$D$90=1,'Control Panel'!$C$90,'Control Panel'!$B$30))^MAX(0,(8-'Control Panel'!$F$49)/2)*0.5 | L22: ='Control Panel'!$B$14*'Control Panel'!$B$7*'Control Panel'!C49*1000000*IF('Control Panel'!$B$100=1,'Control Panel'!K$99,'Control Panel'!$B$28)*'Control Panel'!$B$42*'Control Panel'!$C$42*'Control Panel'!K$56*(1+IF('Control Panel'!$D$90=1,'Control Panel'!$C$90,'Control Panel'!$B$30))^MAX(0,(9-'Control Panel'!$F$49)/2)*0.5 | M22: ='Control Panel'!$B$14*'Control Panel'!$B$7*'Control Panel'!C49*1000000*IF('Control Panel'!$B$100=1,'Control Panel'!L$99,'Control Panel'!$B$28)*'Control Panel'!$B$42*'Control Panel'!$C$42*'Control Panel'!L$56*(1+IF('Control Panel'!$D$90=1,'Control Panel'!$C$90,'Control Panel'!$B$30))^MAX(0,(10-'Control Panel'!$F$49)/2)*0.5 | N22: =SUM(C22:M22)
A23: Trading (5 bps, 100%) | B23: H1 2028 | C23: ='Control Panel'!$B$14*'Control Panel'!$B$8*'Control Panel'!C49*1000000*IF('Control Panel'!$B$100=1,'Control Panel'!B$99,'Control Panel'!$B$28)*'Control Panel'!$B$62*'Control Panel'!$B$43*'Control Panel'!$C$43*'Control Panel'!B$56*(1+IF('Control Panel'!$D$90=1,'Control Panel'!$C$90,'Control Panel'!$B$30))^MAX(0,(0-'Control Panel'!$F$49)/2)*0.5 | D23: ='Control Panel'!$B$14*'Control Panel'!$B$8*'Control Panel'!C49*1000000*IF('Control Panel'!$B$100=1,'Control Panel'!C$99,'Control Panel'!$B$28)*'Control Panel'!$B$62*'Control Panel'!$B$43*'Control Panel'!$C$43*'Control Panel'!C$56*(1+IF('Control Panel'!$D$90=1,'Control Panel'!$C$90,'Control Panel'!$B$30))^MAX(0,(1-'Control Panel'!$F$49)/2)*0.5 | E23: ='Control Panel'!$B$14*'Control Panel'!$B$8*'Control Panel'!C49*1000000*IF('Control Panel'!$B$100=1,'Control Panel'!D$99,'Control Panel'!$B$28)*'Control Panel'!$B$62*'Control Panel'!$B$43*'Control Panel'!$C$43*'Control Panel'!D$56*(1+IF('Control Panel'!$D$90=1,'Control Panel'!$C$90,'Control Panel'!$B$30))^MAX(0,(2-'Control Panel'!$F$49)/2)*0.5 | F23: ='Control Panel'!$B$14*'Control Panel'!$B$8*'Control Panel'!C49*1000000*IF('Control Panel'!$B$100=1,'Control Panel'!E$99,'Control Panel'!$B$28)*'Control Panel'!$B$62*'Control Panel'!$B$43*'Control Panel'!$C$43*'Control Panel'!E$56*(1+IF('Control Panel'!$D$90=1,'Control Panel'!$C$90,'Control Panel'!$B$30))^MAX(0,(3-'Control Panel'!$F$49)/2)*0.5 | G23: ='Control Panel'!$B$14*'Control Panel'!$B$8*'Control Panel'!C49*1000000*IF('Control Panel'!$B$100=1,'Control Panel'!F$99,'Control Panel'!$B$28)*'Control Panel'!$B$62*'Control Panel'!$B$43*'Control Panel'!$C$43*'Control Panel'!F$56*(1+IF('Control Panel'!$D$90=1,'Control Panel'!$C$90,'Control Panel'!$B$30))^MAX(0,(4-'Control Panel'!$F$49)/2)*0.5 | H23: ='Control Panel'!$B$14*'Control Panel'!$B$8*'Control Panel'!C49*1000000*IF('Control Panel'!$B$100=1,'Control Panel'!G$99,'Control Panel'!$B$28)*'Control Panel'!$B$62*'Control Panel'!$B$43*'Control Panel'!$C$43*'Control Panel'!G$56*(1+IF('Control Panel'!$D$90=1,'Control Panel'!$C$90,'Control Panel'!$B$30))^MAX(0,(5-'Control Panel'!$F$49)/2)*0.5 | I23: ='Control Panel'!$B$14*'Control Panel'!$B$8*'Control Panel'!C49*1000000*IF('Control Panel'!$B$100=1,'Control Panel'!H$99,'Control Panel'!$B$28)*'Control Panel'!$B$62*'Control Panel'!$B$43*'Control Panel'!$C$43*'Control Panel'!H$56*(1+IF('Control Panel'!$D$90=1,'Control Panel'!$C$90,'Control Panel'!$B$30))^MAX(0,(6-'Control Panel'!$F$49)/2)*0.5 | J23: ='Control Panel'!$B$14*'Control Panel'!$B$8*'Control Panel'!C49*1000000*IF('Control Panel'!$B$100=1,'Control Panel'!I$99,'Control Panel'!$B$28)*'Control Panel'!$B$62*'Control Panel'!$B$43*'Control Panel'!$C$43*'Control Panel'!I$56*(1+IF('Control Panel'!$D$90=1,'Control Panel'!$C$90,'Control Panel'!$B$30))^MAX(0,(7-'Control Panel'!$F$49)/2)*0.5 | K23: ='Control Panel'!$B$14*'Control Panel'!$B$8*'Control Panel'!C49*1000000*IF('Control Panel'!$B$100=1,'Control Panel'!J$99,'Control Panel'!$B$28)*'Control Panel'!$B$62*'Control Panel'!$B$43*'Control Panel'!$C$43*'Control Panel'!J$56*(1+IF('Control Panel'!$D$90=1,'Control Panel'!$C$90,'Control Panel'!$B$30))^MAX(0,(8-'Control Panel'!$F$49)/2)*0.5 | L23: ='Control Panel'!$B$14*'Control Panel'!$B$8*'Control Panel'!C49*1000000*IF('Control Panel'!$B$100=1,'Control Panel'!K$99,'Control Panel'!$B$28)*'Control Panel'!$B$62*'Control Panel'!$B$43*'Control Panel'!$C$43*'Control Panel'!K$56*(1+IF('Control Panel'!$D$90=1,'Control Panel'!$C$90,'Control Panel'!$B$30))^MAX(0,(9-'Control Panel'!$F$49)/2)*0.5 | M23: ='Control Panel'!$B$14*'Control Panel'!$B$8*'Control Panel'!C49*1000000*IF('Control Panel'!$B$100=1,'Control Panel'!L$99,'Control Panel'!$B$28)*'Control Panel'!$B$62*'Control Panel'!$B$43*'Control Panel'!$C$43*'Control Panel'!L$56*(1+IF('Control Panel'!$D$90=1,'Control Panel'!$C$90,'Control Panel'!$B$30))^MAX(0,(10-'Control Panel'!$F$49)/2)*0.5 | N23: =SUM(C23:M23)
